[2025-03-27T07:40:58.532+0000] {taskinstance.py:1956} INFO - Dependencies all met for dep_context=non-requeueable deps ti=<TaskInstance: test_postgres_conn_dag.check_postgres_connection manual__2025-03-27T07:40:58.325307+00:00 [queued]>
[2025-03-27T07:40:58.540+0000] {taskinstance.py:1956} INFO - Dependencies all met for dep_context=requeueable deps ti=<TaskInstance: test_postgres_conn_dag.check_postgres_connection manual__2025-03-27T07:40:58.325307+00:00 [queued]>
[2025-03-27T07:40:58.541+0000] {taskinstance.py:2170} INFO - Starting attempt 1 of 1
[2025-03-27T07:40:58.550+0000] {taskinstance.py:2191} INFO - Executing <Task(PythonOperator): check_postgres_connection> on 2025-03-27 07:40:58.325307+00:00
[2025-03-27T07:40:58.553+0000] {standard_task_runner.py:60} INFO - Started process 541 to run task
[2025-03-27T07:40:58.555+0000] {standard_task_runner.py:87} INFO - Running: ['***', 'tasks', 'run', 'test_postgres_conn_dag', 'check_postgres_connection', 'manual__2025-03-27T07:40:58.325307+00:00', '--job-id', '14', '--raw', '--subdir', 'DAGS_FOLDER/test_postgres_conn_dag.py', '--cfg-path', '/tmp/tmpdmk94sii']
[2025-03-27T07:40:58.556+0000] {standard_task_runner.py:88} INFO - Job 14: Subtask check_postgres_connection
[2025-03-27T07:40:58.567+0000] {logging_mixin.py:188} WARNING - /home/***/.local/lib/python3.8/site-packages/***/settings.py:194 DeprecationWarning: The sql_alchemy_conn option in [core] has been moved to the sql_alchemy_conn option in [database] - the old setting has been used, but please update your config.
[2025-03-27T07:40:58.589+0000] {task_command.py:423} INFO - Running <TaskInstance: test_postgres_conn_dag.check_postgres_connection manual__2025-03-27T07:40:58.325307+00:00 [running]> on host 2e4f9f51cd78
[2025-03-27T07:40:58.623+0000] {taskinstance.py:2480} INFO - Exporting env vars: AIRFLOW_CTX_DAG_OWNER='***' AIRFLOW_CTX_DAG_ID='test_postgres_conn_dag' AIRFLOW_CTX_TASK_ID='check_postgres_connection' AIRFLOW_CTX_EXECUTION_DATE='2025-03-27T07:40:58.325307+00:00' AIRFLOW_CTX_TRY_NUMBER='1' AIRFLOW_CTX_DAG_RUN_ID='manual__2025-03-27T07:40:58.325307+00:00'
[2025-03-27T07:40:58.627+0000] {base.py:83} INFO - Using connection ID 'postgres_conn' for task execution.
[2025-03-27T07:40:58.628+0000] {logging_mixin.py:188} INFO - âœ… PostgreSQL connected! Server version: PostgreSQL 13.20 (Debian 13.20-1.pgdg120+1) on aarch64-unknown-linux-gnu, compiled by gcc (Debian 12.2.0-14) 12.2.0, 64-bit
[2025-03-27T07:40:58.628+0000] {python.py:201} INFO - Done. Returned value was: None
[2025-03-27T07:40:58.631+0000] {taskinstance.py:1138} INFO - Marking task as SUCCESS. dag_id=test_postgres_conn_dag, task_id=check_postgres_connection, execution_date=20250327T074058, start_date=20250327T074058, end_date=20250327T074058
[2025-03-27T07:40:58.658+0000] {local_task_job_runner.py:234} INFO - Task exited with return code 0
[2025-03-27T07:40:58.664+0000] {taskinstance.py:3280} INFO - 0 downstream tasks scheduled from follow-on schedule check
